Workbook
Name CFA: '31Mar24'!#REF!
Name CFB: '31Mar24'!#REF!
Name CFC: '31Mar24'!#REF!
Name CFD: '31Mar24'!#REF!
Name CFE: '31Mar24'!#REF!
Name CFF: '31Mar24'!#REF!
Name CFG: '31Mar24'!#REF!
Name CFH: '31Mar24'!#REF!
Name CFI: '31Mar24'!#REF!
Name Chol: 'ZCB rates'!#REF!
Name dates: 'ZCB rates'!$B$4:$B$319
Name days_in_year: Assumptions!$D$14
Name DeltaT: 'ZCB rates'!#REF!
Name EPS: 'ZCB rates'!#REF!
Name Hist_conf: #REF!
Name Lambda: Assumptions!$D$19
Name Lambda_hyb: #REF!
Name month_in_a_year: Assumptions!$D$16
Name months_in_a_year: Assumptions!$D$16
Name N_obs_EWMA: #REF!
Name N_obs_hist: #REF!
Name nodes: #REF!
Name Par_conf: #REF!
Name RET_header: 'ZCB rates'!$M$3:$Q$3
Name ZCP_header: 'ZCB rates'!$H$3:$L$3
Name ZCR_header: 'ZCB rates'!$R$3:$V$3

Sheet Cover
C8: Evaluating market risk for fixed income securities
C11: Group 15 - Risk Management and Value in Banking and Insurance
C12: MSc in Finance - 2025/2026
C15: Lorenzo Passioni, Christian Moresco, Raffaele Perillo, Chiara Sacconaghi, Ludovico Raspanti

Sheet Summary
B2: Summary table
B4: Select the desired inputs to below obtain the VaR in cell C9
B5: Date | C5: CI | D5: Method
B6: 45382 | C6: 0.95 | D6: Hybrid approach
B8: Var Value | C8: {=IFERROR(INDEX($C$14:$F$17,MATCH(B6,$B$14:$B$17,0),MATCH(1,(LOOKUP(COLUMN($C$11:$F$11),COLUMN($C$11:$F$11)/($C$11:$F$11<>""),$C$11:$F$11)=D6)*($C$13:$F$13=C6),0)),"Please select the inputs above")} -> 51.377143
C11: Parametric approach (EWMA) | E11: Hybrid approach
C12: Confidence interval
B13: Evaluation date | C13: 0.95 | D13: 0.99 | E13: 0.95 | F13: 0.99
B14: 45382 | C14: =+'31Mar24'!C106 -> 54.324429 | D14: =+'31Mar24'!D106 -> 76.832077 | E14: =+'31Mar24'!C120 -> 51.377143 | F14: =+'31Mar24'!D120 -> 60.071147
B15: 45473 | C15: =+'30Jun24'!C106 -> 35.75704 | D15: =+'30Jun24'!D106 -> 50.571863 | E15: =+'30Jun24'!C120 -> 28.40084 | F15: =+'30Jun24'!D120 -> 53.008952
B16: 45565 | C16: =+'30Sep24'!C106 -> 34.971916 | D16: =+'30Sep24'!D106 -> 49.461449 | E16: =+'30Sep24'!C120 -> 29.42962 | F16: =+'30Sep24'!D120 -> 48.799783
B17: 45657 | C17: =+'31Dec24'!C106 -> 31.689083 | D17: =+'31Dec24'!D106 -> 44.818475 | E17: =+'31Dec24'!C121 -> 27.190894 | F17: =+'31Dec24'!D121 -> 47.085678

Sheet Sheet1
B4: To be selected | D4: To be selected | F4: To be selected
B5: 45382 | D5: 0.95 | F5: Parametric approach (EWMA)
B6: 45473 | D6: 0.99 | F6: Hybrid approach
B7: 45565
B8: 45657

Sheet Inputs -->
D9: Inputs

Sheet Assumptions
B2: Assumptions
B6: Cash flows of the two securities
B7: Security 7 | D7: Dates | E7: 45657 | F7: 45838 | G7: 46022 | H7: 46203 | I7: 46387
D8: Cash flows | E8: 200 | F8: 200 | G8: 200 | H8: 200 | I8: 10200
B10: Security 10 | D10: Dates | E10: 45747 | F10: 45838 | G10: 46022 | H10: 46203
D11: Cash flows | E11: 150 | F11: 150 | G11: 150 | H11: 5150
B14: Days in a year | D14: 365
B16: Months in a year | D16: 12
B19: Lambda | D19: 0.94

Sheet ZCB rates
C2: Zero coupon rates (continuously compounded) | H2: ZCB Prices | M2: Log returns (weekly) | R2: ZCB rates (annually compounded rates)
B3: Date | C3: 3 | D3: 6 | E3: 12 | F3: 24 | G3: 60 | H3: 3 | I3: 6 | J3: 12 | K3: 24 | L3: 60 | M3: 3 | N3: 6 | O3: 12 | P3: 24 | Q3: 60 | R3: 3 | S3: 6 | T3: 12 | U3: 24 | V3: 60
B4: 43829 | C4: -0.005071695 | D4: -0.004933335 | E4: -0.004634075 | F4: -0.003960425 | G4: -0.001580295 | H4: =EXP(-0.25*C4) -> 1.0012687 | I4: =EXP(-0.5*D4) -> 1.0024697 | J4: =EXP(-1*E4) -> 1.0046448 | K4: =EXP(-2*F4) -> 1.0079523 | L4: =EXP(-5*G4) -> 1.0079328 | R4: =+EXP(C4)-1 -> -0.0050588557 | S4: =+EXP(D4)-1 -> -0.0049211861 | T4: =+EXP(E4)-1 -> -0.0046233542 | U4: =+EXP(F4)-1 -> -0.0039525929 | V4: =+EXP(G4)-1 -> -0.001579047
B5: 43836 | C5: -0.005241518 | D5: -0.005084434 | E5: -0.004755086 | F5: -0.004045126 | G5: -0.001664948 | H5: =EXP(-0.25*C5) -> 1.0013112 | I5: =EXP(-0.5*D5) -> 1.0025455 | J5: =EXP(-1*E5) -> 1.0047664 | K5: =EXP(-2*F5) -> 1.0081231 | L5: =EXP(-5*G5) -> 1.0083595 | M5: =+LN(H5/H4) -> 4.245575e-05 | N5: =+LN(I5/I4) -> 7.55495e-05 | O5: =+LN(J5/J4) -> 0.000121011 | P5: =+LN(K5/K4) -> 0.000169402 | Q5: =+LN(L5/L4) -> 0.000423265 | R5: =+EXP(C5)-1 -> -0.0052278052 | S5: =+EXP(D5)-1 -> -0.0050715301 | T5: =+EXP(E5)-1 -> -0.0047437985 | U5: =+EXP(F5)-1 -> -0.0040369555 | V5: =+EXP(G5)-1 -> -0.0016635627
B6: 43843 | C6: -0.005002826 | D6: -0.00482028 | E6: -0.004451986 | F6: -0.003702724 | G6: -0.001373752 | H6: =EXP(-0.25*C6) -> 1.0012515 | I6: =EXP(-0.5*D6) -> 1.002413 | J6: =EXP(-1*E6) -> 1.0044619 | K6: =EXP(-2*F6) -> 1.0074329 | L6: =EXP(-5*G6) -> 1.0068924 | M6: =+LN(H6/H5) -> -5.9673e-05 | N6: =+LN(I6/I5) -> -0.000132077 | O6: =+LN(J6/J5) -> -0.0003031 | P6: =+LN(K6/K5) -> -0.000684804 | Q6: =+LN(L6/L5) -> -0.00145598 | R6: =+EXP(C6)-1 -> -0.0049903327 | S6: =+EXP(D6)-1 -> -0.0048086811 | T6: =+EXP(E6)-1 -> -0.0044420906 | U6: =+EXP(F6)-1 -> -0.0036958774 | V6: =+EXP(G6)-1 -> -0.0013728088
B7: 43850 | C7: -0.004713972 | D7: -0.004548048 | E7: -0.004225668 | F7: -0.003602806 | G7: -0.001719622 | H7: =EXP(-0.25*C7) -> 1.0011792 | I7: =EXP(-0.5*D7) -> 1.0022766 | J7: =EXP(-1*E7) -> 1.0042346 | K7: =EXP(-2*F7) -> 1.0072316 | L7: =EXP(-5*G7) -> 1.0086352 | M7: =+LN(H7/H6) -> -7.22135e-05 | N7: =+LN(I7/I6) -> -0.000136116 | O7: =+LN(J7/J6) -> -0.000226318 | P7: =+LN(K7/K6) -> -0.000199836 | Q7: =+LN(L7/L6) -> 0.00172935 | R7: =+EXP(C7)-1 -> -0.0047028787 | S7: =+EXP(D7)-1 -> -0.0045377213 | T7: =+EXP(E7)-1 -> -0.0042167524 | U7: =+EXP(F7)-1 -> -0.0035963237 | V7: =+EXP(G7)-1 -> -0.0017181443
B8: 43857 | C8: -0.00490369 | D8: -0.00484303 | E8: -0.004707846 | F8: -0.004378868 | G8: -0.002943476 | H8: =EXP(-0.25*C8) -> 1.0012267 | I8: =EXP(-0.5*D8) -> 1.0024244 | J8: =EXP(-1*E8) -> 1.0047189 | K8: =EXP(-2*F8) -> 1.0087962 | L8: =EXP(-5*G8) -> 1.0148262 | M8: =+LN(H8/H7) -> 4.74295e-05 | N8: =+LN(I8/I7) -> 0.000147491 | O8: =+LN(J8/J7) -> 0.000482178 | P8: =+LN(K8/K7) -> 0.001552124 | Q8: =+LN(L8/L7) -> 0.00611927 | R8: =+EXP(C8)-1 -> -0.0048916865 | S8: =+EXP(D8)-1 -> -0.0048313214 | T8: =+EXP(E8)-1 -> -0.0046967815 | U8: =+EXP(F8)-1 -> -0.0043692947 | V8: =+EXP(G8)-1 -> -0.0029391482
B9: 43864 | C9: -0.005149316 | D9: -0.00507515 | E9: -0.004910228 | F9: -0.004516396 | G9: -0.00290901 | H9: =EXP(-0.25*C9) -> 1.0012882 | I9: =EXP(-0.5*D9) -> 1.0025408 | J9: =EXP(-1*E9) -> 1.0049223 | K9: =EXP(-2*F9) -> 1.0090737 | L9: =EXP(-5*G9) -> 1.0146513 | M9: =+LN(H9/H8) -> 6.14065e-05 | N9: =+LN(I9/I8) -> 0.00011606 | O9: =+LN(J9/J8) -> 0.000202382 | P9: =+LN(K9/K8) -> 0.000275056 | Q9: =+LN(L9/L8) -> -0.00017233 | R9: =+EXP(C9)-1 -> -0.005136081 | S9: =+EXP(D9)-1 -> -0.0050622932 | T9: =+EXP(E9)-1 -> -0.0048981925 | U9: =+EXP(F9)-1 -> -0.0045062124 | V9: =+EXP(G9)-1 -> -0.0029047829
B10: 43871 | C10: -0.005274408 | D10: -0.00518219 | E10: -0.004985684 | F10: -0.004548278 | G10: -0.00295818 | H10: =EXP(-0.25*C10) -> 1.0013195 | I10: =EXP(-0.5*D10) -> 1.0025945 | J10: =EXP(-1*E10) -> 1.0049981 | K10: =EXP(-2*F10) -> 1.0091381 | L10: =EXP(-5*G10) -> 1.0149008 | M10: =+LN(H10/H9) -> 3.1273e-05 | N10: =+LN(I10/I9) -> 5.352e-05 | O10: =+LN(J10/J9) -> 7.5456e-05 | P10: =+LN(K10/K9) -> 6.3764e-05 | Q10: =+LN(L10/L9) -> 0.00024585 | R10: =+EXP(C10)-1 -> -0.0052605227 | S10: =+EXP(D10)-1 -> -0.0051687856 | T10: =+EXP(E10)-1 -> -0.0049732761 | U10: =+EXP(F10)-1 -> -0.0045379502 | V10: =+EXP(G10)-1 -> -0.0029538089
B11: 43878 | C11: -0.005192664 | D11: -0.005132996 | E11: -0.00499222 | F11: -0.004634458 | G11: -0.003117912 | H11: =EXP(-0.25*C11) -> 1.001299 | I11: =EXP(-0.5*D11) -> 1.0025698 | J11: =EXP(-1*E11) -> 1.0050047 | K11: =EXP(-2*F11) -> 1.009312 | L11: =EXP(-5*G11) -> 1.0157117 | M11: =+LN(H11/H10) -> -2.0436e-05 | N11: =+LN(I11/I10) -> -2.4597e-05 | O11: =+LN(J11/J10) -> 6.536e-06 | P11: =+LN(K11/K10) -> 0.00017236 | Q11: =+LN(L11/L10) -> 0.00079866 | R11: =+EXP(C11)-1 -> -0.0051792054 | S11: =+EXP(D11)-1 -> -0.0051198447 | T11: =+EXP(E11)-1 -> -0.0049797796 | U11: =+EXP(F11)-1 -> -0.0046237355 | V11: =+EXP(G11)-1 -> -0.0031130564
B12: 43885 | C12: -0.005246292 | D12: -0.00517287 | E12: -0.005010478 | F12: -0.004630088 | G12: -0.00315976 | H12: =EXP(-0.25*C12) -> 1.0013124 | I12: =EXP(-0.5*D12) -> 1.0025898 | J12: =EXP(-1*E12) -> 1.0050231 | K12: =EXP(-2*F12) -> 1.0093032 | L12: =EXP(-5*G12) -> 1.0159243 | M12: =+LN(H12/H11) -> 1.3407e-05 | N12: =+LN(I12/I11) -> 1.9937e-05 | O12: =+LN(J12/J11) -> 1.8258e-05 | P12: =+LN(K12/K11) -> -8.74e-06 | Q12: =+LN(L12/L11) -> 0.00020924 | R12: =+EXP(C12)-1 -> -0.0052325542 | S12: =+EXP(D12)-1 -> -0.0051595137 | T12: =+EXP(E12)-1 -> -0.0049979465 | U12: =+EXP(F12)-1 -> -0.0046193857 | V12: =+EXP(G12)-1 -> -0.0031547732
B13: 43892 | C13: -0.005320852 | D13: -0.005283442 | E13: -0.005181416 | F13: -0.004882578 | G13: -0.00346323 | H13: =EXP(-0.25*C13) -> 1.0013311 | I13: =EXP(-0.5*D13) -> 1.0026452 | J13: =EXP(-1*E13) -> 1.0051949 | K13: =EXP(-2*F13) -> 1.009813 | L13: =EXP(-5*G13) -> 1.0174669 | M13: =+LN(H13/H12) -> 1.864e-05 | N13: =+LN(I13/I12) -> 5.5286e-05 | O13: =+LN(J13/J12) -> 0.000170938 | P13: =+LN(K13/K12) -> 0.00050498 | Q13: =+LN(L13/L12) -> 0.00151735 | R13: =+EXP(C13)-1 -> -0.0053067213 | S13: =+EXP(D13)-1 -> -0.0052695092 | T13: =+EXP(E13)-1 -> -0.0051680156 | U13: =+EXP(F13)-1 -> -0.0048706776 | V13: =+EXP(G13)-1 -> -0.0034572399
B14: 43899 | C14: -0.004679946 | D14: -0.004643822 | E14: -0.004528996 | F14: -0.00416294 | G14: -0.002469534 | H14: =EXP(-0.25*C14) -> 1.0011707 | I14: =EXP(-0.5*D14) -> 1.0023246 | J14: =EXP(-1*E14) -> 1.0045393 | K14: =EXP(-2*F14) -> 1.0083606 | L14: =EXP(-5*G14) -> 1.0124242 | M14: =+LN(H14/H13) -> -0.0001602265 | N14: =+LN(I14/I13) -> -0.00031981 | O14: =+LN(J14/J13) -> -0.00065242 | P14: =+LN(K14/K13) -> -0.001439276 | Q14: =+LN(L14/L13) -> -0.00496848 | R14: =+EXP(C14)-1 -> -0.0046690121 | S14: =+EXP(D14)-1 -> -0.0046330561 | T14: =+EXP(E14)-1 -> -0.0045187556 | U14: =+EXP(F14)-1 -> -0.004154287 | V14: =+EXP(G14)-1 -> -0.0024664872
B15: 43906 | C15: -0.00348285 | D15: -0.002853954 | E15: -0.001859882 | F15: -0.000498352 | G15: 0.002173908 | H15: =EXP(-0.25*C15) -> 1.0008711 | I15: =EXP(-0.5*D15) -> 1.001428 | J15: =EXP(-1*E15) -> 1.0018616 | K15: =EXP(-2*F15) -> 1.0009972 | L15: =EXP(-5*G15) -> 0.98918932 | M15: =+LN(H15/H14) -> -0.000299274 | N15: =+LN(I15/I14) -> -0.000894934 | O15: =+LN(J15/J14) -> -0.002669114 | P15: =+LN(K15/K14) -> -0.007329176 | Q15: =+LN(L15/L14) -> -0.02321721 | R15: =+EXP(C15)-1 -> -0.0034767919 | S15: =+EXP(D15)-1 -> -0.0028498853 | T15: =+EXP(E15)-1 -> -0.0018581535 | U15: =+EXP(F15)-1 -> -0.00049822784 | V15: =+EXP(G15)-1 -> 0.0021762727
B16: 43913 | C16: -0.003760184 | D16: -0.003383794 | E16: -0.002786454 | F16: -0.001920582 | G16: 0.000398698 | H16: =EXP(-0.25*C16) -> 1.0009405 | I16: =EXP(-0.5*D16) -> 1.0016933 | J16: =EXP(-1*E16) -> 1.0027903 | K16: =EXP(-2*F16) -> 1.0038486 | L16: =EXP(-5*G16) -> 0.9980085 | M16: =+LN(H16/H15) -> 6.93335e-05 | N16: =+LN(I16/I15) -> 0.00026492 | O16: =+LN(J16/J15) -> 0.000926572 | P16: =+LN(K16/K15) -> 0.00284446 | Q16: =+LN(L16/L15) -> 0.00887605 | R16: =+EXP(C16)-1 -> -0.0037531234 | S16: =+EXP(D16)-1 -> -0.0033780754 | T16: =+EXP(E16)-1 -> -0.0027825754 | U16: =+EXP(F16)-1 -> -0.0019187389 | V16: =+EXP(G16)-1 -> 0.00039877749
... B319: 46034 | C319: 0.020262282 | D319: 0.020258162 | E319: 0.02043664 | F319: 0.021377836 | G319: 0.025927362 | H319: =EXP(-0.25*C319) -> 0.99494724 | I319: =EXP(-0.5*D319) -> 0.98992205 | J319: =EXP(-1*E319) -> 0.97977077 | K319: =EXP(-2*F319) -> 0.95814546 | L319: =EXP(-5*G319) -> 0.8784144 | M319: =+LN(H319/H318) -> 2.3407e-05 | N319: =+LN(I319/I318) -> 1.8497e-05 | O319: =+LN(J319/J318) -> 8.574e-06 | P319: =+LN(K319/K318) -> 0.0001871 | Q319: =+LN(L319/L318) -> 0.00173182 | R319: =+EXP(C319)-1 -> 0.020468956 | S319: =+EXP(D319)-1 -> 0.020464751 | T319: =+EXP(E319)-1 -> 0.020646898 | U319: =+EXP(F319)-1 -> 0.021607979 | V319: =+EXP(G319)-1 -> 0.0262664

Sheet Computations -->
D9: Computations

Sheet 31Mar24
B3: Legend
D5: Cashflows to be clumped
D6: Cashflows already at the correct nodes
B9: Date at which cashflows must be computed
B11: VaR comp. date | C11: 45382
B13: Nodes | C13: =+EOMONTH($C$11,'ZCB rates'!C$3) -> 45473 | D13: =+EOMONTH($C$11,'ZCB rates'!D$3) -> 45565 | E13: =+EOMONTH($C$11,'ZCB rates'!E$3) -> 45747 | F13: =+EOMONTH($C$11,'ZCB rates'!F$3) -> 46112 | G13: =+EOMONTH($C$11,'ZCB rates'!G$3) -> 47208
B14: Diff from today (days) | C14: =+C13-C11 -> 91 | D14: =+D13-$C$11 -> 183 | E14: =+E13-$C$11 -> 365 | F14: =+F13-$C$11 -> 730 | G14: =+G13-$C$11 -> 1826
B17: Term structure of int rates
C19: =+'ZCB rates'!C3 -> 3 | D19: =+'ZCB rates'!D3 -> 6 | E19: =+'ZCB rates'!E3 -> 12 | F19: =+'ZCB rates'!F3 -> 24 | G19: =+'ZCB rates'!G3 -> 60
B20: =+C11 -> 45382 | C20: =+'ZCB rates'!R225 -> 0.039148292 | D20: =+'ZCB rates'!S225 -> 0.037100348 | E20: =+'ZCB rates'!T225 -> 0.033890367 | F20: =+'ZCB rates'!U225 -> 0.030018486 | G20: =+'ZCB rates'!V225 -> 0.027648924
B23: Security 7
C26: =+Assumptions!E7 -> 45657 | D26: =+Assumptions!F7 -> 45838 | E26: =+Assumptions!G7 -> 46022 | F26: =+Assumptions!H7 -> 46203 | G26: =+Assumptions!I7 -> 46387
B27: t from today (duration) | C27: =+(C26-$C$11)/365 -> 0.75342466 | D27: =+(D26-$C$11)/365 -> 1.2493151 | E27: =+(E26-$C$11)/365 -> 1.7534247 | F27: =+(F26-$C$11)/365 -> 2.2493151 | G27: =+(G26-$C$11)/365 -> 2.7534247
B28: Interpolated rate | C28: =+_xlfn.LET(_xlpm.t_remaining,C27,_xlpm.r_m1,D20,_xlpm.r_m2,E20,_xlpm.mone,D19,_xlpm.mtwo,E19,_xlpm.r_m1+(_xlpm.r_m2-_xlpm.r_m1)/(_xlpm.mtwo/month_in_a_year-_xlpm.mone/month_in_a_year)*(_xlpm.t_remaining-_xlpm.mone/month_in_a_year)) -> 0.035473372 | D28: =+_xlfn.LET(_xlpm.t_rem,D27,_xlpm.r_m1,E20,_xlpm.r_m2,F20,_xlpm.mone,E19,_xlpm.mtwo,F19,_xlpm.r_m1+(_xlpm.r_m2-_xlpm.r_m1)/(_xlpm.mtwo/month_in_a_year-_xlpm.mone/month_in_a_year)*(_xlpm.t_rem-_xlpm.mone/month_in_a_year)) -> 0.032925049 | E28: =+_xlfn.LET(_xlpm.t_rem,E27,_xlpm.r_m1,E20,_xlpm.r_m2,F20,_xlpm.mone,E19,_xlpm.mtwo,F19,_xlpm.r_m1+(_xlpm.r_m2-_xlpm.r_m1)/(_xlpm.mtwo/month_in_a_year-_xlpm.mone/month_in_a_year)*(_xlpm.t_rem-_xlpm.mone/month_in_a_year)) -> 0.030973197 | F28: =+_xlfn.LET(_xlpm.t_rem,F27,_xlpm.r_m1,F20,_xlpm.r_m2,G20,_xlpm.mone,F19,_xlpm.mtwo,G19,_xlpm.r_m1+(_xlpm.r_m2-_xlpm.r_m1)/(_xlpm.mtwo/month_in_a_year-_xlpm.mone/month_in_a_year)*(_xlpm.t_rem-_xlpm.mone/month_in_a_year)) -> 0.029821564 | G28: =+_xlfn.LET(_xlpm.t_rem,G27,_xlpm.r_m1,F20,_xlpm.r_m2,G20,_xlpm.mone,F19,_xlpm.mtwo,G19,_xlpm.r_m1+(_xlpm.r_m2-_xlpm.r_m1)/(_xlpm.mtwo/month_in_a_year-_xlpm.mone/month_in_a_year)*(_xlpm.t_rem-_xlpm.mone/month_in_a_year)) -> 0.029423391
B29: Modified Duration | C29: =+C27/(1+C28) -> 0.72761374 | D29: =+D27/(1+D28) -> 1.2094925 | E29: =+E27/(1+E28) -> 1.7007471 | F29: =+F27/(1+F28) -> 2.1841794 | G29: =+G27/(1+G28) -> 2.6747252
B31: Goal nodes | C31: 6m & 12m | D31: 12m & 24m | E31: 12m & 24m | F31: 24m & 60m | G31: 24m & 60m
B32: MD 1 | C32: =+(D$19/month_in_a_year)/(1+D$20) -> 0.48211342 | D32: =+(E$19/month_in_a_year)/(1+E$20) -> 0.96722054 | E32: =+(E$19/month_in_a_year)/(1+E$20) -> 0.96722054 | F32: =+(F$19/month_in_a_year)/(1+F$20) -> 1.9417127 | G32: =+(F$19/month_in_a_year)/(1+F$20) -> 1.9417127
B33: MD 2 | C33: =+(E$19/month_in_a_year)/(1+E$20) -> 0.96722054 | D33: =+(F$19/month_in_a_year)/(1+F$20) -> 1.9417127 | E33: =+(F$19/month_in_a_year)/(1+F$20) -> 1.9417127 | F33: =+(G$19/month_in_a_year)/(1+G$20) -> 4.8654749 | G33: =+(G$19/month_in_a_year)/(1+G$20) -> 4.8654749
B35: Market value real cashflow | C35: =+Assumptions!E$8/(1+C28)^C27 -> 194.8157 | D35: =+Assumptions!F8/(1+D28)^D27 -> 192.06738 | E35: =+Assumptions!G8/(1+E28)^E27 -> 189.58402 | F35: =+Assumptions!H8/(1+F28)^F27 -> 187.20795 | G35: =+Assumptions!I8/(1+G28)^G27 -> 9417.236
B37: Mkt value virtual cashflow 1 | C37: =+_xlfn.LET(_xlpm.MDvirt1,C32,_xlpm.MDvirt2,C33,_xlpm.MDreal,C29,_xlpm.Mvreal,C35,(_xlpm.MDvirt2-_xlpm.MDreal)/(_xlpm.MDvirt2-_xlpm.MDvirt1)*_xlpm.Mvreal) -> 96.224449 | D37: =+_xlfn.LET(_xlpm.MDvirt1,D32,_xlpm.MDvirt2,D33,_xlpm.MDreal,D29,_xlpm.Mvreal,D35,(_xlpm.MDvirt2-_xlpm.MDreal)/(_xlpm.MDvirt2-_xlpm.MDvirt1)*_xlpm.Mvreal) -> 144.31684 | E37: =+_xlfn.LET(_xlpm.MDvirt1,E32,_xlpm.MDvirt2,E33,_xlpm.MDreal,E29,_xlpm.Mvreal,E35,(_xlpm.MDvirt2-_xlpm.MDreal)/(_xlpm.MDvirt2-_xlpm.MDvirt1)*_xlpm.Mvreal) -> 46.879015 | F37: =+_xlfn.LET(_xlpm.MDvirt1,F32,_xlpm.MDvirt2,F33,_xlpm.MDreal,F29,_xlpm.Mvreal,F35,(_xlpm.MDvirt2-_xlpm.MDreal)/(_xlpm.MDvirt2-_xlpm.MDvirt1)*_xlpm.Mvreal) -> 171.68285 | G37: =+_xlfn.LET(_xlpm.MDvirt1,G32,_xlpm.MDvirt2,G33,_xlpm.MDreal,G29,_xlpm.Mvreal,G35,(_xlpm.MDvirt2-_xlpm.MDreal)/(_xlpm.MDvirt2-_xlpm.MDvirt1)*_xlpm.Mvreal) -> 7056.2535
B38: Mkt value Virtual cashflow 2 | C38: =+C35-C37 -> 98.591249 | D38: =+D35-D37 -> 47.750548 | E38: =+E35-E37 -> 142.705 | F38: =+F35-F37 -> 15.525098 | G38: =+G35-G37 -> 2360.9825
B40: Face value 1 | C40: =+C37*(1+D20)^(D19/month_in_a_year) -> 97.993174 | D40: =+D37*(1+E20)^(E19/month_in_a_year) -> 149.20779 | E40: =+E37*(1+E20)^(E19/month_in_a_year) -> 48.467762 | F40: =+F37*(1+F20)^(F19/month_in_a_year) -> 182.14487 | G40: =+G37*(1+F20)^(F19/month_in_a_year) -> 7486.248
B41: Face value 2 | C41: =+C38*(1+E20)^(E19/month_in_a_year) -> 101.93254 | D41: =+D38*(1+F20)^(F19/month_in_a_year) -> 50.660375 | E41: =+E38*(1+F20)^(F19/month_in_a_year) -> 151.40117 | F41: =+F38*(1+G20)^(G19/month_in_a_year) -> 17.79337 | G41: =+G38*(1+G20)^(G19/month_in_a_year) -> 2705.9304
B43: Check | C43: =ROUND(+C29-C32*C37/C35-C33*C38/C35,5) -> 0 | D43: =ROUND(+D29-D32*D37/D35-D33*D38/D35,5) -> 0 | E43: =ROUND(+E29-E32*E37/E35-E33*E38/E35,5) -> 0 | F43: =ROUND(+F29-F32*F37/F35-F33*F38/F35,5) -> 0 | G43: =+G29-G32*G37/G35-G33*G38/G35 -> 0
B47: Security 10
C50: =+Assumptions!E10 -> 45747 | D50: =+Assumptions!F10 -> 45838 | E50: =+Assumptions!G10 -> 46022 | F50: =+Assumptions!H10 -> 46203
B51: t from today (duration) | C51: =+(C50-$C$11)/365 -> 1 | D51: =+(D50-$C$11)/365 -> 1.2493151 | E51: =+(E50-$C$11)/365 -> 1.7534247 | F51: =+(F50-$C$11)/365 -> 2.2493151
B52: Interpolated rate | D52: =+_xlfn.LET(_xlpm.t_rem,D51,_xlpm.r_m1,E20,_xlpm.r_m2,F20,_xlpm.mone,E19,_xlpm.mtwo,F19,_xlpm.r_m1+(_xlpm.r_m2-_xlpm.r_m1)/(_xlpm.mtwo/month_in_a_year-_xlpm.mone/month_in_a_year)*(_xlpm.t_rem-_xlpm.mone/month_in_a_year)) -> 0.032925049 | E52: =+_xlfn.LET(_xlpm.t_rem,E51,_xlpm.r_m1,E20,_xlpm.r_m2,F20,_xlpm.mone,E19,_xlpm.mtwo,F19,_xlpm.r_m1+(_xlpm.r_m2-_xlpm.r_m1)/(_xlpm.mtwo/month_in_a_year-_xlpm.mone/month_in_a_year)*(_xlpm.t_rem-_xlpm.mone/month_in_a_year)) -> 0.030973197 | F52: =+_xlfn.LET(_xlpm.t_rem,F51,_xlpm.r_m1,F20,_xlpm.r_m2,G20,_xlpm.mone,F19,_xlpm.mtwo,G19,_xlpm.r_m1+(_xlpm.r_m2-_xlpm.r_m1)/(_xlpm.mtwo/month_in_a_year-_xlpm.mone/month_in_a_year)*(_xlpm.t_rem-_xlpm.mone/month_in_a_year)) -> 0.029821564
B53: Modified Duration | D53: =+D51/(1+D52) -> 1.2094925 | E53: =+E51/(1+E52) -> 1.7007471 | F53: =+F51/(1+F52) -> 2.1841794
B55: Goal nodes | C55: 12m | D55: 12m & 24m | E55: 12m & 24m | F55: 24m & 60m
B56: MD 1 | D56: =+(E$19/12)/(1+E$20) -> 0.96722054 | E56: =+(E$19/12)/(1+E$20) -> 0.96722054 | F56: =+(F$19/12)/(1+F$20) -> 1.9417127
B57: MD 2 | D57: =+(F$19/12)/(1+F$20) -> 1.9417127 | E57: =+(F$19/12)/(1+F$20) -> 1.9417127 | F57: =+(G$19/12)/(1+G$20) -> 4.8654749
B59: Market value real cashflow | C59: =C64/(1+E20) -> 145.08308 | D59: =+Assumptions!F$11/(1+D52)^D51 -> 144.05054 | E59: =+Assumptions!G$11/(1+E52)^E51 -> 142.18801 | F59: =+Assumptions!H$11/(1+F52)^F51 -> 4820.6046
B61: Mkt value Virtual cashflow 1 | D61: =+_xlfn.LET(_xlpm.MDvirt1,D56,_xlpm.MDvirt2,D57,_xlpm.MDreal,D53,_xlpm.Mvreal,D59,(_xlpm.MDvirt2-_xlpm.MDreal)/(_xlpm.MDvirt2-_xlpm.MDvirt1)*_xlpm.Mvreal) -> 108.23763 | E61: =+_xlfn.LET(_xlpm.MDvirt1,E56,_xlpm.MDvirt2,E57,_xlpm.MDreal,E53,_xlpm.Mvreal,E59,(_xlpm.MDvirt2-_xlpm.MDreal)/(_xlpm.MDvirt2-_xlpm.MDvirt1)*_xlpm.Mvreal) -> 35.159262 | F61: =+_xlfn.LET(_xlpm.MDvirt1,F56,_xlpm.MDvirt2,F57,_xlpm.MDreal,F53,_xlpm.Mvreal,F59,(_xlpm.MDvirt2-_xlpm.MDreal)/(_xlpm.MDvirt2-_xlpm.MDvirt1)*_xlpm.Mvreal) -> 4420.8333
B62: Mkt value Virtual cashflow 2 | D62: =+D59-D61 -> 35.812911 | E62: =+E59-E61 -> 107.02875 | F62: =+F59-F61 -> 399.77127
B64: Face value 1 | C64: =Assumptions!E11 -> 150 | D64: =+D61*(1+E20)^(E19/month_in_a_year) -> 111.90584 | E64: =+E61*(1+E20)^(E19/month_in_a_year) -> 36.350822 | F64: =+F61*(1+F20)^(F19/month_in_a_year) -> 4690.2305
B65: Face value 2 | C65: 0 | D65: =+D62*(1+F20)^(F19/month_in_a_year) -> 37.995281 | E65: =+E62*(1+F20)^(F19/month_in_a_year) -> 113.55088 | F65: =+F62*(1+G20)^(G19/month_in_a_year) -> 458.17927
B67: Check | D67: =ROUND(+D53-D56*D61/D59-D57*D62/D59,5) -> 0 | E67: =ROUND(+E53-E56*E61/E59-E57*E62/E59,5) -> 0 | F67: =ROUND(+F53-F56*F61/F59-F57*F62/F59,5) -> 0
B69: New Portfolio
C71: =+C72-$C$11 -> 91 | D71: =+D72-$C$11 -> 183 | E71: =+E72-$C$11 -> 365 | F71: =+F72-$C$11 -> 730 | G71: =+G72-$C$11 -> 1826
...

Sheet 30Jun24
B3: Legend
D5: Cashflows to be clumped
D6: Cashflows already at the correct nodes
B9: Date at which cashflows must be computed
B11: VaR comp. date | C11: 45473
B13: Nodes | C13: =+EOMONTH($C$11,'ZCB rates'!C$3) -> 45565 | D13: =+EOMONTH($C$11,'ZCB rates'!D$3) -> 45657 | E13: =+EOMONTH($C$11,'ZCB rates'!E$3) -> 45838 | F13: =+EOMONTH($C$11,'ZCB rates'!F$3) -> 46203 | G13: =+EOMONTH($C$11,'ZCB rates'!G$3) -> 47299
B14: Diff from today | C14: =+C13-$C$11 -> 92 | D14: =+D13-$C$11 -> 184 | E14: =+E13-$C$11 -> 365 | F14: =+F13-$C$11 -> 730 | G14: =+G13-$C$11 -> 1826
B17: Term structure of int rates
C19: =+'ZCB rates'!C3 -> 3 | D19: =+'ZCB rates'!D3 -> 6 | E19: =+'ZCB rates'!E3 -> 12 | F19: =+'ZCB rates'!F3 -> 24 | G19: =+'ZCB rates'!G3 -> 60
B20: =+C11 -> 45473 | C20: ='ZCB rates'!R238 -> 0.036486102 | D20: ='ZCB rates'!S238 -> 0.035332016 | E20: ='ZCB rates'!T238 -> 0.03345475 | F20: ='ZCB rates'!U238 -> 0.031036344 | G20: ='ZCB rates'!V238 -> 0.029483088
B23: Security 7
C26: =+Assumptions!E7 -> 45657 | D26: =+Assumptions!F7 -> 45838 | E26: =+Assumptions!G7 -> 46022 | F26: =+Assumptions!H7 -> 46203 | G26: =+Assumptions!I7 -> 46387
B27: t from today (duration) | C27: =+(C26-$C$11)/365 -> 0.50410959 | D27: =+(D26-$C$11)/365 -> 1 | E27: =+(E26-$C$11)/365 -> 1.5041096 | F27: =+(F26-$C$11)/365 -> 2 | G27: =+(G26-$C$11)/365 -> 2.5041096
B28: Interpolated rate | E28: =+_xlfn.LET(_xlpm.t_rem,E27,_xlpm.r_m1,E20,_xlpm.r_m2,F20,_xlpm.mone,E19,_xlpm.mtwo,F19,_xlpm.r_m1+(_xlpm.r_m2-_xlpm.r_m1)/(_xlpm.mtwo/month_in_a_year-_xlpm.mone/month_in_a_year)*(_xlpm.t_rem-_xlpm.mone/month_in_a_year)) -> 0.032235609 | G28: =+_xlfn.LET(_xlpm.t_rem,G27,_xlpm.r_m1,F20,_xlpm.r_m2,G20,_xlpm.mone,F19,_xlpm.mtwo,G19,_xlpm.r_m1+(_xlpm.r_m2-_xlpm.r_m1)/(_xlpm.mtwo/month_in_a_year-_xlpm.mone/month_in_a_year)*(_xlpm.t_rem-_xlpm.mone/month_in_a_year)) -> 0.030775341
B29: Modified Duration | E29: =+E27/(1+E28) -> 1.4571379 | G29: =+G27/(1+G28) -> 2.4293456
B31: Goal nodes | C31: 6m | D31: 12m | E31: 12m & 24m | F31: 24m | G31: 24m & 60m
B32: MD 1 | E32: =+(E$19/month_in_a_year)/(1+E$20) -> 0.96762824 | G32: =+(F$19/month_in_a_year)/(1+F$20) -> 1.9397958
B33: MD 2 | E33: =+(F$19/month_in_a_year)/(1+F$20) -> 1.9397958 | G33: =+(G$19/month_in_a_year)/(1+G$20) -> 4.8568064
B35: Market value real cashflow | C35: =Assumptions!E8/(1+D20)^C27 -> 196.52971 | D35: =Assumptions!F8/(1+'30Jun24'!E20)^'30Jun24'!D27 -> 193.52565 | E35: =+Assumptions!G8/(1+E28)^E27 -> 190.67999 | F35: =F40/(1+F20)^F27 -> 188.14039 | G35: =+Assumptions!I8/(1+G28)^G27 -> 9454.4446
B37: Mkt value virtual cashflow | E37: =+_xlfn.LET(_xlpm.MDvirt1,E32,_xlpm.MDvirt2,E33,_xlpm.MDreal,E29,_xlpm.Mvreal,E35,(_xlpm.MDvirt2-_xlpm.MDreal)/(_xlpm.MDvirt2-_xlpm.MDvirt1)*_xlpm.Mvreal) -> 94.668055 | G37: =+_xlfn.LET(_xlpm.MDvirt1,G32,_xlpm.MDvirt2,G33,_xlpm.MDreal,G29,_xlpm.Mvreal,G35,(_xlpm.MDvirt2-_xlpm.MDreal)/(_xlpm.MDvirt2-_xlpm.MDvirt1)*_xlpm.Mvreal) -> 7867.7443
B38: Mkt value Virtual cashflow | E38: =+E35-E37 -> 96.011933 | G38: =+G35-G37 -> 1586.7004
B40: Face value 1 | C40: =Assumptions!E8 -> 200 | D40: =Assumptions!F8 -> 200 | E40: =+E37*(1+E20)^(E19/month_in_a_year) -> 97.835151 | F40: =Assumptions!H8 -> 200 | G40: =+G37*(1+F20)^(F19/month_in_a_year) -> 8363.6949
B41: Face value 2 | E41: =+E38*(1+F20)^(F19/month_in_a_year) -> 102.06414 | G41: =+G38*(1+G20)^(G19/month_in_a_year) -> 1834.8096
B43: Check | E43: =ROUND(+E29-E32*E37/E35-E33*E38/E35,5) -> 0 | G43: =+G29-G32*G37/G35-G33*G38/G35 -> 0
B47: Security 10
C50: =+Assumptions!E10 -> 45747 | D50: =+Assumptions!F10 -> 45838 | E50: =+Assumptions!G10 -> 46022 | F50: =+Assumptions!H10 -> 46203
B51: t from today (duration) | C51: =+(C50-$C$11)/365 -> 0.75068493 | D51: =+(D50-$C$11)/365 -> 1 | E51: =+(E50-$C$11)/365 -> 1.5041096 | F51: =+(F50-$C$11)/365 -> 2
B52: Interpolated rate | C52: =+_xlfn.LET(_xlpm.t_rem,C51,_xlpm.r_m1,D20,_xlpm.r_m2,E20,_xlpm.mone,D19,_xlpm.mtwo,E19,_xlpm.r_m1+(_xlpm.r_m2-_xlpm.r_m1)/(_xlpm.mtwo/month_in_a_year-_xlpm.mone/month_in_a_year)*(_xlpm.t_rem-_xlpm.mone/month_in_a_year)) -> 0.034390812 | E52: =+_xlfn.LET(_xlpm.t_rem,E51,_xlpm.r_m1,E20,_xlpm.r_m2,F20,_xlpm.mone,E19,_xlpm.mtwo,F19,_xlpm.r_m1+(_xlpm.r_m2-_xlpm.r_m1)/(_xlpm.mtwo/month_in_a_year-_xlpm.mone/month_in_a_year)*(_xlpm.t_rem-_xlpm.mone/month_in_a_year)) -> 0.032235609
B53: Modified Duration | C53: =+C51/(1+C52) -> 0.7257266 | E53: =+E51/(1+E52) -> 1.4571379
B55: Goal nodes | C55: 6m & 12m | D55: 12m | E55: 12m & 24m | F55: 24m
B56: MD 1 | C56: =+(D$19/12)/(1+D$20) -> 0.48293687 | E56: =+(E$19/12)/(1+E$20) -> 0.96762824
B57: MD 2 | C57: =+(E$19/12)/(1+E$20) -> 0.96762824 | E57: =+(F$19/12)/(1+F$20) -> 1.9397958
B59: Market value real cashflow | C59: =+Assumptions!E$11/(1+C52)^C51 -> 146.24052 | D59: =D64/(1+E20)^D51 -> 145.14424 | E59: =+Assumptions!G$11/(1+E52)^E51 -> 143.00999 | F59: =F64/(1+F20)^F51 -> 4844.6151
B61: Mkt value Virtual cashflow 1 | C61: =+_xlfn.LET(_xlpm.MDvirt1,C56,_xlpm.MDvirt2,C57,_xlpm.MDreal,C53,_xlpm.Mvreal,C59,(_xlpm.MDvirt2-_xlpm.MDreal)/(_xlpm.MDvirt2-_xlpm.MDvirt1)*_xlpm.Mvreal) -> 72.986279 | E61: =+_xlfn.LET(_xlpm.MDvirt1,E56,_xlpm.MDvirt2,E57,_xlpm.MDreal,E53,_xlpm.Mvreal,E59,(_xlpm.MDvirt2-_xlpm.MDreal)/(_xlpm.MDvirt2-_xlpm.MDvirt1)*_xlpm.Mvreal) -> 71.001041
B62: Mkt value Virtual cashflow 2 | C62: =+C59-C61 -> 73.254237 | E62: =+E59-E61 -> 72.008949
B64: Face value 1 | C64: =+C61*(1+D20)^(D19/month_in_a_year) -> 74.264463 | D64: =Assumptions!F11 -> 150 | E64: =+E61*(1+E20)^(E19/month_in_a_year) -> 73.376363 | F64: =Assumptions!H11 -> 5150
B65: Face value 2 | C65: =+C62*(1+E20)^(E19/month_in_a_year) -> 75.704939 | E65: =+E62*(1+F20)^(F19/month_in_a_year) -> 76.548102
B67: Check | C67: =ROUND(+C53-C56*C61/C59-C57*C62/C59,5) -> 0 | E67: =ROUND(+E53-E56*E61/E59-E57*E62/E59,5) -> 0
B69: New Portfolio
C71: =+C72-$C$11 -> 92 | D71: =+D72-$C$11 -> 184 | E71: =+E72-$C$11 -> 365 | F71: =+F72-$C$11 -> 730 | G71: =+G72-$C$11 -> 1826
...

Sheet 30Sep24
B3: Legend
D5: Cashflows to be clumped
D6: Cashflows already at the correct nodes
B9: Date at which cashflows must be computed
B11: VaR comp. date | C11: 45565
B13: Nodes | C13: =+EOMONTH($C$11,'ZCB rates'!C$3) -> 45657 | D13: =+EOMONTH($C$11,'ZCB rates'!D$3) -> 45747 | E13: =+EOMONTH($C$11,'ZCB rates'!E$3) -> 45930 | F13: =+EOMONTH($C$11,'ZCB rates'!F$3) -> 46295 | G13: =+EOMONTH($C$11,'ZCB rates'!G$3) -> 47391
B14: Diff from today | C14: =+C13-$C$11 -> 92 | D14: =+D13-$C$11 -> 182 | E14: =+E13-$C$11 -> 365 | F14: =+F13-$C$11 -> 730 | G14: =+G13-$C$11 -> 1826
B17: Term structure of int rates
C19: =+'ZCB rates'!C3 -> 3 | D19: =+'ZCB rates'!D3 -> 6 | E19: =+'ZCB rates'!E3 -> 12 | F19: =+'ZCB rates'!F3 -> 24 | G19: =+'ZCB rates'!G3 -> 60
B20: =+C11 -> 45565 | C20: ='ZCB rates'!R252 -> 0.032779852 | D20: ='ZCB rates'!S252 -> 0.029806831 | E20: ='ZCB rates'!T252 -> 0.025732802 | F20: ='ZCB rates'!U252 -> 0.022240957 | G20: ='ZCB rates'!V252 -> 0.023772414
B23: Security 7
C26: =+Assumptions!E7 -> 45657 | D26: =+Assumptions!F7 -> 45838 | E26: =+Assumptions!G7 -> 46022 | F26: =+Assumptions!H7 -> 46203 | G26: =+Assumptions!I7 -> 46387
B27: t from today (duration) | C27: =+(C26-$C$11)/365 -> 0.25205479 | D27: =+(D26-$C$11)/365 -> 0.74794521 | E27: =+(E26-$C$11)/365 -> 1.2520548 | F27: =+(F26-$C$11)/365 -> 1.7479452 | G27: =+(G26-$C$11)/365 -> 2.2520548
B28: Interpolated rate | D28: =+_xlfn.LET(_xlpm.t_rem,D27,_xlpm.r_m1,D20,_xlpm.r_m2,E20,_xlpm.mone,D19,_xlpm.mtwo,E19,_xlpm.r_m1+(_xlpm.r_m2-_xlpm.r_m1)/(_xlpm.mtwo/month_in_a_year-_xlpm.mone/month_in_a_year)*(_xlpm.t_rem-_xlpm.mone/month_in_a_year)) -> 0.027786559 | E28: =+_xlfn.LET(_xlpm.t_rem,E27,_xlpm.r_m1,E20,_xlpm.r_m2,F20,_xlpm.mone,E19,_xlpm.mtwo,F19,_xlpm.r_m1+(_xlpm.r_m2-_xlpm.r_m1)/(_xlpm.mtwo/month_in_a_year-_xlpm.mone/month_in_a_year)*(_xlpm.t_rem-_xlpm.mone/month_in_a_year)) -> 0.024852666 | F28: =+_xlfn.LET(_xlpm.t_rem,F27,_xlpm.r_m1,E20,_xlpm.r_m2,F20,_xlpm.mone,E19,_xlpm.mtwo,F19,_xlpm.r_m1+(_xlpm.r_m2-_xlpm.r_m1)/(_xlpm.mtwo/month_in_a_year-_xlpm.mone/month_in_a_year)*(_xlpm.t_rem-_xlpm.mone/month_in_a_year)) -> 0.023121093 | G28: =+_xlfn.LET(_xlpm.t_rem,G27,_xlpm.r_m1,F20,_xlpm.r_m2,G20,_xlpm.mone,F19,_xlpm.mtwo,G19,_xlpm.r_m1+(_xlpm.r_m2-_xlpm.r_m1)/(_xlpm.mtwo/month_in_a_year-_xlpm.mone/month_in_a_year)*(_xlpm.t_rem-_xlpm.mone/month_in_a_year)) -> 0.022369627
B29: Modified Duration | D29: =+D27/(1+D28) -> 0.72772425 | E29: =+E27/(1+E28) -> 1.2216925 | F29: =+F27/(1+F28) -> 1.7084441 | G29: =+G27/(1+G28) -> 2.2027794
B31: Goal nodes | C31: 3m | D31: 6m & 12m | E31: 12m & 24m | F31: 12m & 24m | G31: 24m & 60m
B32: MD 1 | D32: =+(D$19/month_in_a_year)/(1+D$20) -> 0.48552795 | E32: =+(E$19/month_in_a_year)/(1+E$20) -> 0.97491276 | F32: =+(E$19/month_in_a_year)/(1+E$20) -> 0.97491276 | G32: =+(F$19/month_in_a_year)/(1+F$20) -> 1.9564859
B33: MD 2 | D33: =+(E$19/month_in_a_year)/(1+E$20) -> 0.97491276 | E33: =+(F$19/month_in_a_year)/(1+F$20) -> 1.9564859 | F33: =+(F$19/month_in_a_year)/(1+F$20) -> 1.9564859 | G33: =+(G$19/month_in_a_year)/(1+G$20) -> 4.883898
B35: Market value real cashflow | C35: =C40/(1+C20)^C27 -> 198.38063 | D35: =+Assumptions!F8/(1+D28)^D27 -> 195.94187 | E35: =+Assumptions!G8/(1+E28)^E27 -> 193.94621 | F35: =+Assumptions!H8/(1+F28)^F27 -> 192.16668 | G35: =+Assumptions!I8/(1+G28)^G27 -> 9704.2632
B37: Mkt value virtual cashflow | D37: =+_xlfn.LET(_xlpm.MDvirt1,D32,_xlpm.MDvirt2,D33,_xlpm.MDreal,D29,_xlpm.Mvreal,D35,(_xlpm.MDvirt2-_xlpm.MDreal)/(_xlpm.MDvirt2-_xlpm.MDvirt1)*_xlpm.Mvreal) -> 98.970336 | E37: =+_xlfn.LET(_xlpm.MDvirt1,E32,_xlpm.MDvirt2,E33,_xlpm.MDreal,E29,_xlpm.Mvreal,E35,(_xlpm.MDvirt2-_xlpm.MDreal)/(_xlpm.MDvirt2-_xlpm.MDvirt1)*_xlpm.Mvreal) -> 145.18571 | F37: =+_xlfn.LET(_xlpm.MDvirt1,F32,_xlpm.MDvirt2,F33,_xlpm.MDreal,F29,_xlpm.Mvreal,F35,(_xlpm.MDvirt2-_xlpm.MDreal)/(_xlpm.MDvirt2-_xlpm.MDvirt1)*_xlpm.Mvreal) -> 48.560175 | G37: =+_xlfn.LET(_xlpm.MDvirt1,G32,_xlpm.MDvirt2,G33,_xlpm.MDreal,G29,_xlpm.Mvreal,G35,(_xlpm.MDvirt2-_xlpm.MDreal)/(_xlpm.MDvirt2-_xlpm.MDvirt1)*_xlpm.Mvreal) -> 8887.8091
B38: Mkt value Virtual cashflow | D38: =+D35-D37 -> 96.971536 | E38: =+E35-E37 -> 48.760494 | F38: =+F35-F37 -> 143.6065 | G38: =+G35-G37 -> 816.45407
B40: Face value 1 | C40: =Assumptions!E8 -> 200 | D40: =+D37*(1+D20)^(D19/month_in_a_year) -> 100.4345 | E40: =+E37*(1+E20)^(E19/month_in_a_year) -> 148.92175 | F40: =+F37*(1+E20)^(E19/month_in_a_year) -> 49.809765 | G40: =+G37*(1+F20)^(F19/month_in_a_year) -> 9287.5523
B41: Face value 2 | D41: =+D38*(1+E20)^(E19/month_in_a_year) -> 99.466885 | E41: =+E38*(1+F20)^(F19/month_in_a_year) -> 50.953574 | F41: =+F38*(1+F20)^(F19/month_in_a_year) -> 150.06543 | G41: =+G38*(1+G20)^(G19/month_in_a_year) -> 918.2245
B43: Check | C43: =ROUND(+C29-C32*C37/C35-C33*C38/C35,5) -> 0 | D43: =ROUND(+D29-D32*D37/D35-D33*D38/D35,5) -> 0 | E43: =ROUND(+E29-E32*E37/E35-E33*E38/E35,5) -> 0 | F43: =+F29-F32*F37/F35-F33*F38/F35 -> 0 | G43: =+G29-G32*G37/G35-G33*G38/G35 -> 0
B47: Security 10
C50: =+Assumptions!E10 -> 45747 | D50: =+Assumptions!F10 -> 45838 | E50: =+Assumptions!G10 -> 46022 | F50: =+Assumptions!H10 -> 46203
B51: t from today (duration) | C51: =+(C50-$C$11)/365 -> 0.49863014 | D51: =+(D50-$C$11)/365 -> 0.74794521 | E51: =+(E50-$C$11)/365 -> 1.2520548 | F51: =+(F50-$C$11)/365 -> 1.7479452
B52: Interpolated rate | D52: =+_xlfn.LET(_xlpm.t_rem,D51,_xlpm.r_m1,D20,_xlpm.r_m2,E20,_xlpm.mone,D19,_xlpm.mtwo,E19,_xlpm.r_m1+(_xlpm.r_m2-_xlpm.r_m1)/(_xlpm.mtwo/month_in_a_year-_xlpm.mone/month_in_a_year)*(_xlpm.t_rem-_xlpm.mone/month_in_a_year)) -> 0.027786559 | E52: =+_xlfn.LET(_xlpm.t_rem,E51,_xlpm.r_m1,E20,_xlpm.r_m2,F20,_xlpm.mone,E19,_xlpm.mtwo,F19,_xlpm.r_m1+(_xlpm.r_m2-_xlpm.r_m1)/(_xlpm.mtwo/month_in_a_year-_xlpm.mone/month_in_a_year)*(_xlpm.t_rem-_xlpm.mone/month_in_a_year)) -> 0.024852666 | F52: =+_xlfn.LET(_xlpm.t_rem,F51,_xlpm.r_m1,E20,_xlpm.r_m2,F20,_xlpm.mone,E19,_xlpm.mtwo,F19,_xlpm.r_m1+(_xlpm.r_m2-_xlpm.r_m1)/(_xlpm.mtwo/month_in_a_year-_xlpm.mone/month_in_a_year)*(_xlpm.t_rem-_xlpm.mone/month_in_a_year)) -> 0.023121093
B53: Modified Duration | D53: =+D51/(1+D52) -> 0.72772425 | E53: =+E51/(1+E52) -> 1.2216925 | F53: =+F51/(1+F52) -> 1.7084441
B55: Goal nodes | C55: 6m | D55: 6m & 12m | E55: 12m & 24m | F55: 12m & 24m
B56: MD 1 | D56: =+(D$19/12)/(1+D$20) -> 0.48552795 | E56: =+(E$19/12)/(1+E$20) -> 0.97491276 | F56: =+(E$19/12)/(1+E$20) -> 0.97491276
B57: MD 2 | D57: =+(E$19/12)/(1+E$20) -> 0.97491276 | E57: =+(F$19/12)/(1+F$20) -> 1.9564859 | F57: =+(F$19/12)/(1+F$20) -> 1.9564859
B59: Market value real cashflow | C59: =C64/(1+D20)^C51 -> 147.8192 | D59: =+Assumptions!F$11/(1+D52)^D51 -> 146.9564 | E59: =+Assumptions!G$11/(1+E52)^E51 -> 145.45966 | F59: =+Assumptions!H$11/(1+F52)^F51 -> 4948.2919
B61: Mkt value virtual cashflow | D61: =+_xlfn.LET(_xlpm.MDvirt1,D56,_xlpm.MDvirt2,D57,_xlpm.MDreal,D53,_xlpm.Mvreal,D59,(_xlpm.MDvirt2-_xlpm.MDreal)/(_xlpm.MDvirt2-_xlpm.MDvirt1)*_xlpm.Mvreal) -> 74.227752 | E61: =+_xlfn.LET(_xlpm.MDvirt1,E56,_xlpm.MDvirt2,E57,_xlpm.MDreal,E53,_xlpm.Mvreal,E59,(_xlpm.MDvirt2-_xlpm.MDreal)/(_xlpm.MDvirt2-_xlpm.MDvirt1)*_xlpm.Mvreal) -> 108.88929 | F61: =+_xlfn.LET(_xlpm.MDvirt1,F56,_xlpm.MDvirt2,F57,_xlpm.MDreal,F53,_xlpm.Mvreal,F59,(_xlpm.MDvirt2-_xlpm.MDreal)/(_xlpm.MDvirt2-_xlpm.MDvirt1)*_xlpm.Mvreal) -> 1250.4245
B62: Mkt value Virtual cashflow | D62: =+D59-D61 -> 72.728652 | E62: =+E59-E61 -> 36.570371 | F62: =+F59-F61 -> 3697.8674
B64: Face value 1 | C64: =Assumptions!E11 -> 150 | D64: =+D61*(1+D20)^(D19/month_in_a_year) -> 75.325876 | E64: =+E61*(1+E20)^(E19/month_in_a_year) -> 111.69131 | F64: =+F61*(1+E20)^(E19/month_in_a_year) -> 1282.6014
B65: Face value 2 | D65: =+D62*(1+E20)^(E19/month_in_a_year) -> 74.600164 | E65: =+E62*(1+F20)^(F19/month_in_a_year) -> 38.215181 | F65: =+F62*(1+F20)^(F19/month_in_a_year) -> 3864.1848
B67: Check | C67: =ROUND(+C53-C56*C61/C59-C57*C62/C59,5) -> 0 | D67: =ROUND(+D53-D56*D61/D59-D57*D62/D59,5) -> 0 | E67: =ROUND(+E53-E56*E61/E59-E57*E62/E59,5) -> 0 | F67: =ROUND(+F53-F56*F61/F59-F57*F62/F59,5) -> 0
B69: New Portfolio
C71: =+C72-$C$11 -> 92 | D71: =+D72-$C$11 -> 182 | E71: =+E72-$C$11 -> 365 | F71: =+F72-$C$11 -> 730 | G71: =+G72-$C$11 -> 1826
...

Sheet 31Dec24
B3: Legend
D5: Cashflows to be clumped
D6: Cashflows already at the correct nodes
B9: Date at which cashflows must be computed
B11: VaR comp. date | C11: 45657
B13: Nodes | C13: =+EOMONTH($C$11,'ZCB rates'!C$3) -> 45747 | D13: =+EOMONTH($C$11,'ZCB rates'!D$3) -> 45838 | E13: =+EOMONTH($C$11,'ZCB rates'!E$3) -> 46022 | F13: =+EOMONTH($C$11,'ZCB rates'!F$3) -> 46387 | G13: =+EOMONTH($C$11,'ZCB rates'!G$3) -> 47483
B14: Diff from today | C14: =+C13-$C$11 -> 90 | D14: =+D13-$C$11 -> 181 | E14: =+E13-$C$11 -> 365 | F14: =+F13-$C$11 -> 730 | G14: =+G13-$C$11 -> 1826
B17: Term structure of int rates
C19: =+'ZCB rates'!C3 -> 3 | D19: =+'ZCB rates'!D3 -> 6 | E19: =+'ZCB rates'!E3 -> 12 | F19: =+'ZCB rates'!F3 -> 24 | G19: =+'ZCB rates'!G3 -> 60
B20: =+C11 -> 45657 | C20: ='ZCB rates'!R265 -> 0.027300204 | D20: ='ZCB rates'!S265 -> 0.025143067 | E20: ='ZCB rates'!T265 -> 0.022922954 | F20: ='ZCB rates'!U265 -> 0.0222462 | G20: ='ZCB rates'!V265 -> 0.02569348
B23: Security 7
C26: =+Assumptions!F7 -> 45838 | D26: =+Assumptions!G7 -> 46022 | E26: =+Assumptions!H7 -> 46203 | F26: =+Assumptions!I7 -> 46387
B27: t from today (duration) | C27: =+(C26-$C$11)/365 -> 0.49589041 | D27: =+(D26-$C$11)/365 -> 1 | E27: =+(E26-$C$11)/365 -> 1.4958904 | F27: =+(F26-$C$11)/365 -> 2
B28: Interpolated rate | E28: =+_xlfn.LET(_xlpm.t_rem,E27,_xlpm.r_m1,E20,_xlpm.r_m2,F20,_xlpm.mone,E19,_xlpm.mtwo,F19,_xlpm.r_m1+(_xlpm.r_m2-_xlpm.r_m1)/(_xlpm.mtwo/month_in_a_year-_xlpm.mone/month_in_a_year)*(_xlpm.t_rem-_xlpm.mone/month_in_a_year)) -> 0.022587358
B29: Modified Duration | E29: =+E27/(1+E28) -> 1.4628485
B31: Goal nodes | C31: 6m | D31: 12m | E31: 12m & 24m | F31: 24m
B32: MD 1 | E32: =+(E$19/month_in_a_year)/(1+E$20) -> 0.97759073
B33: MD 2 | E33: =+(F$19/month_in_a_year)/(1+F$20) -> 1.9564758
B35: Market value real cashflow | C35: =Assumptions!F8/(1+D20)^C27 -> 197.55229 | D35: =Assumptions!G8/(1+E20)^D27 -> 195.51815 | E35: =+Assumptions!H8/(1+E28)^E27 -> 193.42795 | F35: =Assumptions!I8/(1+F20)^F27 -> 9760.8842
B37: Mkt value virtual cashflow | E37: =+_xlfn.LET(_xlpm.MDvirt1,E32,_xlpm.MDvirt2,E33,_xlpm.MDreal,E29,_xlpm.Mvreal,E35,(_xlpm.MDvirt2-_xlpm.MDreal)/(_xlpm.MDvirt2-_xlpm.MDvirt1)*_xlpm.Mvreal) -> 97.540886
B38: Mkt value Virtual cashflow | E38: =+E35-E37 -> 95.887065
B40: Face value 1 | C40: =Assumptions!F8 -> 200 | D40: =Assumptions!G8 -> 200 | E40: =+E37*(1+E20)^(E19/month_in_a_year) -> 99.776811 | F40: =Assumptions!I8 -> 10200
B41: Face value 2 | E41: =+E38*(1+F20)^(F19/month_in_a_year) -> 100.20076
B43: Check | E43: =+E29-E32*E37/E35-E33*E38/E35 -> 0
B47: Security 10
C50: =+Assumptions!E10 -> 45747 | D50: =+Assumptions!F10 -> 45838 | E50: =+Assumptions!G10 -> 46022 | F50: =+Assumptions!H10 -> 46203
B51: t from today (duration) | C51: =+(C50-$C$11)/365 -> 0.24657534 | D51: =+(D50-$C$11)/365 -> 0.49589041 | E51: =+(E50-$C$11)/365 -> 1 | F51: =+(F50-$C$11)/365 -> 1.4958904
B52: Interpolated rate | F52: =+_xlfn.LET(_xlpm.t_rem,F51,_xlpm.r_m1,E20,_xlpm.r_m2,F20,_xlpm.mone,E19,_xlpm.mtwo,F19,_xlpm.r_m1+(_xlpm.r_m2-_xlpm.r_m1)/(_xlpm.mtwo/month_in_a_year-_xlpm.mone/month_in_a_year)*(_xlpm.t_rem-_xlpm.mone/month_in_a_year)) -> 0.022587358
B53: Modified Duration | F53: =+F51/(1+F52) -> 1.4628485
B55: Goal nodes | C55: 3m | D55: 6m | E55: 12m | F55: 12m & 24m
B56: MD 1 | F56: =+(E$19/12)/(1+E$20) -> 0.97759073
B57: MD 2 | F57: =+(F$19/12)/(1+F$20) -> 1.9564758
B59: Market value real cashflow | C59: =Assumptions!E11/(1+C20)^C51 -> 149.0071 | D59: =Assumptions!F11/(1+D20)^D51 -> 148.16422 | E59: =Assumptions!G11/(1+E20)^E51 -> 146.63861 | F59: =+Assumptions!H$11/(1+F52)^F51 -> 4980.7697
B61: Mkt value virtual cashflow | F61: =+_xlfn.LET(_xlpm.MDvirt1,F56,_xlpm.MDvirt2,F57,_xlpm.MDreal,F53,_xlpm.Mvreal,F59,(_xlpm.MDvirt2-_xlpm.MDreal)/(_xlpm.MDvirt2-_xlpm.MDvirt1)*_xlpm.Mvreal) -> 2511.6778
B62: Mkt value Virtual cashflow | F62: =+F59-F61 -> 2469.0919
B64: Face value 1 | C64: =Assumptions!E11 -> 150 | D64: =Assumptions!F11 -> 150 | E64: =Assumptions!G11 -> 150 | F64: =+F61*(1+E20)^(E19/month_in_a_year) -> 2569.2529
B65: Face value 2 | F65: =+F62*(1+F20)^(F19/month_in_a_year) -> 2580.1697
B67: Check | F67: =+F53-F56*F61/F59-F57*F62/F59 -> 0
B69: New Portfolio
C71: =+C72-$C$11 -> 90 | D71: =+D72-$C$11 -> 181 | E71: =+E72-$C$11 -> 365 | F71: =+F72-$C$11 -> 730 | G71: =+G72-$C$11 -> 1826
...
